<?xml version="1.0"?>
<robot name="aubo_N30">
  <dh_type type="modified"/>
  <safety_para singularity_consistent="0.02 0.01 10 0.2 0.045 10"/>
  <friction_coeff value="0.65"/>
  <link name="link0">
    <inertial>
      <origin xyz="0.000229 0.001159 0.034428" rpy="0 0 0" />
      <mass value="5.346475" />
      <inertia ixx="0.032233" ixy="0.000005" ixz="-0.000002" iyy="0.031749" iyz="-0.000139" izz="0.054685" />					
    </inertial>
    <visual>
      <origin xyz="0 0 0" rpy="0 0 0" />
      <geometry>
        <mesh filename="package://aubo_description/meshes/aubo_N30/visual/link0.DAE" />
      </geometry>
      <material name="">
        <color rgba="1 1 1 1" />
      </material>
    </visual>
    <collision>
      <origin xyz="0 0 0" rpy="0 0 0" />
      <geometry>
        <mesh filename="package://aubo_description/meshes/aubo_N30/collision/link0.STL" />
      </geometry>
    </collision>
  </link>

  <link name="link1">
    <inertial>
      <origin xyz="-0.000063 0.005306 -0.037423" rpy="0 0 0" />
      <mass value="19.848224" />
      <inertia ixx="0.141701" ixy="-0.000011" ixz="0.000006" iyy="0.139553" iyz="-0.004204" izz="0.107794" />					
    </inertial>
    <visual>
      <origin xyz="0 0 0" rpy="0 0 0" />
      <geometry>
        <mesh filename="package://aubo_description/meshes/aubo_N30/visual/link1.DAE" />
      </geometry>
      <material name="">
        <color rgba="1 1 1 1" />
      </material>
    </visual>
    <collision>
      <origin xyz="0 0 0" rpy="0 0 0" />
      <geometry>
        <mesh filename="package://aubo_description/meshes/aubo_N30/collision/link1.STL" />
      </geometry>
    </collision>
  </link>

  <joint name="joint1" type="revolute">
    <origin xyz="0 0 0.2105" rpy="0 0 3.1415926535897932384626433832795" />
    <parent link="link0" />
    <child link="link1" />
    <axis xyz="0 0 1" />
    <limit lower="-6.283185307179586476925286766559" upper="6.283185307179586476925286766559" effort="819" start_stop="1147" velocity="2.487094" />
    <property inertia="9.5" damping="0" stiffness="0" offset="0" motor_constant="16.66" ratio="160"/>
  </joint>

  <link name="link2">
    <inertial>
      <origin xyz="0.39065382 0.00001621 0.04630441" rpy="0 0 0" />
      <mass value="45.85382997" />							
      <inertia ixx="0.29704511" ixy="0.00072005" ixz="-0.07473281" iyy="0.07473281" iyz="0.00001435" izz="6.92255682" />
    </inertial>
    <visual>
      <origin xyz="0 0 0" rpy="0 0 0" />
      <geometry>
        <mesh filename="package://aubo_description/meshes/aubo_N30/visual/link2.DAE" />
      </geometry>
      <material name="">
        <color rgba="1 1 1 1" />
      </material>
    </visual>
    <collision>
      <origin xyz="0 0 0" rpy="0 0 0" />
      <geometry>
        <mesh filename="package://aubo_description/meshes/aubo_N30/collision/link2.STL" />
      </geometry>
    </collision>
  </link>

  <joint name="joint2" type="revolute">
    <origin xyz="0 0.1835 0" rpy="-1.5707963267948966192313216916398 -1.5707963267948966192313216916398 0" />
    <parent link="link1" />
    <child link="link2" />
    <axis xyz="0 0 1" />
    <limit lower="-6.283185307179586476925286766559" upper="6.283185307179586476925286766559" effort="819" start_stop="1147" velocity="2.487094" />
    <property inertia="9.5" damping="0" stiffness="0" offset="0" motor_constant="16.66" ratio="160"/>
  </joint>

  <link name="link3">
    <inertial>
      <origin xyz="0.4445061 -0.00001 0.145985" rpy="0 0 0" />
      <mass value="11.527" />
      <inertia ixx="0.071784" ixy="-0.000066" ixz="0.02179" iyy="2.585683" iyz="0.000005" izz="2.581688" />
    </inertial>
    <visual>
      <origin xyz="0 0 0" rpy="0 0 0" />
      <geometry>
        <mesh filename="package://aubo_description/meshes/aubo_N30/visual/link3.DAE" />
      </geometry>
      <material name="">
        <color rgba="1 1 1 1" />
      </material>
    </visual>
    <collision>
      <origin xyz="0 0 0" rpy="0 0 0" />
      <geometry>
        <mesh filename="package://aubo_description/meshes/aubo_N30/collision/link3.STL" />
      </geometry>
    </collision>
  </link>

  <joint name="foreArm_joint" type="revolute">
    <origin xyz="0.856 0 0" rpy="-3.1415926535897932384626433832795 0 0" />
    <parent link="link2" />
    <child link="link3" />
    <axis xyz="0 0 1" />
    <limit lower="-3.0543261909900767596164588448551" upper="3.0543261909900767596164588448551" effort="484" start_stop="738" velocity="4.18879" />
    <property inertia="0" damping="0" stiffness="0" offset="0" motor_constant="0" ratio="100"/>
  </joint>

  <link name="link4">
    <inertial>
      <origin xyz="0.000010 0.019300 -0.001720" rpy="0 0 0" />
      <mass value="2.8906100" />
      <inertia ixx="0.004670" ixy="-0.000000" ixz="-0.000000" iyy="0.003320" iyz="-0.000120" izz="0.004640" />						
    </inertial>
    <visual>
      <origin xyz="0 0 0" rpy="0 0 0" />
      <geometry>
        <mesh filename="package://aubo_description/meshes/aubo_N30/visual/link4.DAE" />
      </geometry>
      <material name="">
        <color rgba="1 1 1 1" />
      </material>
    </visual>
    <collision>
      <origin xyz="0 0 0" rpy="0 0 0" />
      <geometry>
        <mesh filename="package://aubo_description/meshes/aubo_N30/collision/link4.STL" />
      </geometry>
    </collision>
  </link>

  <joint name="joint4" type="revolute">
    <origin xyz="0.826 0 0" rpy="3.1415926535897932384626433832795 0 1.5707963267948966192313216916398" />
    <parent link="link3" />
    <child link="link4" />
    <axis xyz="0 0 1" />
    <limit lower="-3.0543261909900767596164588448551" upper="3.0543261909900767596164588448551" effort="61" start_stop="96" velocity="6.806784" />
    <property inertia="0" damping="0" stiffness="0" offset="0" motor_constant="0" ratio="80"/>
  </joint>

  <link name="link5">
    <inertial>
      <origin xyz="-0.000010 -0.019300 -0.001720" rpy="0 0 0" />
      <mass value="2.8906100" />
      <inertia ixx="0.004670" ixy="-0.000000" ixz="-0.000000" iyy="0.003320" iyz="0.000120" izz="0.004640" />
    </inertial>
    <visual>
      <origin xyz="0 0 0" rpy="0 0 0" />
      <geometry>
        <mesh filename="package://aubo_description/meshes/aubo_N30/visual/link5.DAE" />
      </geometry>
      <material name="">
        <color rgba="1 1 1 1" />
      </material>
    </visual>
    <collision>
      <origin xyz="0 0 0" rpy="0 0 0" />
      <geometry>
        <mesh filename="package://aubo_description/meshes/aubo_N30/collision/link5.STL" />
      </geometry>
    </collision>
  </link>

  <joint name="joint5" type="revolute">
    <origin xyz="0 0.125 0" rpy="-1.5707963267948966192313216916398 0 0" />
    <parent link="link4" />
    <child link="link5" />
    <axis xyz="0 0 1" />
    <limit lower="-3.0543261909900767596164588448551" upper="3.0543261909900767596164588448551" effort="61" start_stop="96" velocity="6.806784" />
    <property inertia="0" damping="0" stiffness="0" offset="0" motor_constant="0" ratio="80"/>
  </joint>

  <link name="link6">
    <inertial>
      <origin xyz="0 0 -0.022644" rpy="0 0 0" />
      <mass value="0.825555" />
      <inertia ixx="0.001087" ixy="0" ixz="0" iyy="0.001087" iyz="0" izz="0.001832" />
    </inertial>
    <visual>
      <origin xyz="0 0 0" rpy="0 0 0" />
      <geometry>
        <mesh filename="package://aubo_description/meshes/aubo_N30/visual/link6.DAE" />
      </geometry>
      <material name="">
        <color rgba="1 1 1 1" />
      </material>
    </visual>
    <collision>
      <origin xyz="0 0 0" rpy="0 0 0" />
      <geometry>
        <mesh filename="package://aubo_description/meshes/aubo_N30/collision/link6.STL" />
      </geometry>
    </collision>
  </link>

  <joint name="joint6" type="revolute">
    <origin xyz="0 -0.1295 0" rpy="1.5707963267948966192313216916398 0 0" />
    <parent link="link5" />
    <child link="link6" />
    <axis xyz="0 0 1" />
    <limit lower="-3.0543261909900767596164588448551" upper="3.0543261909900767596164588448551" effort="61" start_stop="96" velocity="6.806784" />
    <property inertia="0" damping="0" stiffness="0" offset="0" motor_constant="0" ratio="80"/>
  </joint>

  <link name="world" />

  <joint name="joint0" type="fixed">
    <parent link="world" />
    <child link = "link0" />
    <origin xyz="0.0 0.0 0.0" rpy="0.0 0.0 0.0" />
  </joint>
</robot>
