<?xml version="1.0"?>
<robot  name="aubo_G10">
  <dh_type type="modified"/>
  <safety_para singularity_consistent="0.02 0.01 10 0.2 0.045 10"/>	
  <link name="link0">
    <inertial>
      <origin xyz="0.00038 0.00471 0.01913" rpy="0 0 0" />
      <mass value="2.02203" />
      <inertia ixx="0.00676" ixy="-0.00004" ixz="0.00001" iyy="0.00628" iyz="-0.00007" izz="0.01215" />
    </inertial>
    <visual>
      <origin xyz="0 0 0" rpy="0 0 0" />
      <geometry>
        <mesh filename="package://aubo_description/meshes/aubo_G10/visual/link0.DAE" />
      </geometry>
      <material name="">
        <color rgba="1 1 1 1" />
      </material>
    </visual>
    <collision>
      <origin xyz="0 0 0" rpy="0 0 0" />
      <geometry>
        <mesh filename="package://aubo_description/meshes/aubo_G10/collision/link0.STL" />
      </geometry>
    </collision>
  </link>

  <link name="link1">
    <inertial>
      <origin xyz="0.000013 0.00391 -0.027601" rpy="0 0 0" />
      <mass value="9.55599784" />
      <inertia ixx="0.03704" ixy="0.00001" ixz="0.00004" iyy="0.03629" iyz="-0.00112" izz="0.02738" />
    </inertial>
    <visual>
      <origin xyz="0 0 0" rpy="0 0 0" />
      <geometry>
        <mesh filename="package://aubo_description/meshes/aubo_G10/visual/link1.DAE" />
      </geometry>
      <material name="">
        <color rgba="1 1 1 1" />
      </material>
    </visual>
    <collision>
      <origin xyz="0 0 0" rpy="0 0 0" />
      <geometry>
        <mesh filename="package://aubo_description/meshes/aubo_G10/collision/link1.STL" />
      </geometry>
    </collision>
  </link>

  <joint name="joint1" type="revolute">
    <origin xyz="0 0 0.157" rpy="0 0 3.1415926535897932384626433832795" />
    <parent link="link0" />
    <child link="link1" />
    <axis xyz="0 0 1" />
    <limit lower="-6.283185307179586476925286766559" upper="6.283185307179586476925286766559" effort="281" start_stop="433" velocity="5.026548" />
    <property inertia="4.9" damping="0" stiffness="0" offset="0" motor_constant="9.54" ratio="100"/>
  </joint>

  <link name="link2">
    <inertial>
      <origin xyz="0.21436 0.00001 -0.01184" rpy="0 0 0" />
      <mass value="16.7475" />
      <inertia ixx="0.0561" ixy="0.00005" ixz="-0.02225" iyy="1.25634" iyz="-0.00003" izz="1.24286" />
    </inertial>
    <visual>
      <origin xyz="0 0 0" rpy="0 0 0" />
      <geometry>
        <mesh filename="package://aubo_description/meshes/aubo_G10/visual/link2.DAE" />
      </geometry>
      <material name="">
        <color rgba="1 1 1 1" />
      </material>
    </visual>
    <collision>
      <origin xyz="0 0 0" rpy="0 0 0" />
      <geometry>
        <mesh filename="package://aubo_description/meshes/aubo_G10/collision/link2.STL" />
      </geometry>
    </collision>
  </link>

  <joint name="joint2" type="revolute">
    <origin xyz="0 0.185 0" rpy="-1.5707963267948966192313216916398 -1.5707963267948966192313216916398 0" />
    <parent link="link1" />
    <child link="link2" />
    <axis xyz="0 0 1" />
    <limit lower="-6.283185307179586476925286766559" upper="6.283185307179586476925286766559" effort="281" start_stop="433" velocity="5.026548" />
    <property inertia="4.9" damping="0" stiffness="0" offset="0" motor_constant="9.54" ratio="100"/>
  </joint>

  <link name="link3">
    <inertial>
      <origin xyz="0.42241 0.0 0.10169" rpy="0 0 0" />
      <mass  value="3.93199" />
      <inertia ixx="0.00586" ixy="0.00001" ixz="0.00193" iyy="0.17192" iyz="0" izz="0.1708" />
    </inertial>
    <visual>
      <origin xyz="0 0 0" rpy="0 0 0" />
      <geometry>
        <mesh filename="package://aubo_description/meshes/aubo_G10/visual/link3.DAE" />
      </geometry>
      <material name="">
        <color rgba="1 1 1 1" />
      </material>
    </visual>
    <collision>
      <origin xyz="0 0 0" rpy="0 0 0" />
      <geometry>
        <mesh filename="package://aubo_description/meshes/aubo_G10/collision/link3.STL" />
      </geometry>
    </collision>
  </link>

  <joint name="foreArm_joint" type="revolute">
    <origin xyz="0.613 0 0" rpy="-3.1415926535897932384626433832795 0 0" />
    <parent link="link2" />
    <child link="link3" />
    <axis xyz="0 0 1" />
    <limit lower="-6.283185307179586476925286766559" upper="6.283185307179586476925286766559" effort="140" start_stop="204" velocity="5.864306" />
    <property inertia="0.77" damping="0" stiffness="0" offset="0" motor_constant="8.72" ratio="100"/>
  </joint>

  <link name="link4">
    <inertial>
      <origin xyz="0.00 0.01586 -0.00161" rpy="0 0 0" />
      <mass value="1.49768" />
      <inertia ixx="0.00317" ixy="0" ixz="0" iyy="0.00202" iyz="-0.00007" izz="0.00314" />
    </inertial>
    <visual>
      <origin xyz="0 0 0" rpy="0 0 0" />
      <geometry>
        <mesh filename="package://aubo_description/meshes/aubo_G10/visual/link4.DAE" />
      </geometry>
      <material name="">
        <color rgba="1 1 1 1" />
      </material>
    </visual>
    <collision>
      <origin xyz="0 0 0" rpy="0 0 0" />
      <geometry>
        <mesh filename="package://aubo_description/meshes/aubo_G10/collision/link4.STL" />
      </geometry>
    </collision>
  </link>

  <joint name="joint4" type="revolute">
    <origin xyz="0.572 0 0" rpy="3.1415926535897932384626433832795 0 1.5707963267948966192313216916398" />
    <parent link="link3" />
    <child link="link4" />
    <axis xyz="0 0 1" />
    <limit lower="-6.283185307179586476925286766559" upper="6.283185307179586476925286766559" effort="51" start_stop="70" velocity="7.644542" />
    <property inertia="0.25" damping="0" stiffness="0" offset="0" motor_constant="8.81" ratio="100"/>
  </joint>

  <link name="link5">
    <inertial>
      <origin xyz="0.000 -0.01586 -0.00161" rpy="0 0 0" />
      <mass value="1.49768" />
      <inertia ixx="0.00317" ixy="0" ixz="0" iyy="0.00202" iyz="0.00007" izz="0.00314" />
    </inertial>
    <visual>
      <origin xyz="0 0 0" rpy="0 0 0" />
      <geometry>
        <mesh filename="package://aubo_description/meshes/aubo_G10/visual/link5.DAE" />
      </geometry>
      <material name="">
        <color rgba="1 1 1 1" />
      </material>
    </visual>
    <collision>
      <origin xyz="0 0 0" rpy="0 0 0" />
      <geometry>
        <mesh filename="package://aubo_description/meshes/aubo_G10/collision/link5.STL" />
      </geometry>
    </collision>
  </link>

  <joint name="joint5" type="revolute">
    <origin xyz="0 0.115 0" rpy="-1.5707963267948966192313216916398 0 0" />
    <parent link="link4" />
    <child link="link5" />
    <axis xyz="0 0 1" />
    <limit lower="-6.283185307179586476925286766559" upper="6.283185307179586476925286766559" effort="14" start_stop="36" velocity="8.901179" />
    <property inertia="0.25" damping="0" stiffness="0" offset="0" motor_constant="8.81" ratio="100"/>
  </joint>

  <link name="link6">
    <inertial>
      <origin xyz="-0.00076 0.00033 -0.01811" rpy="0 0 0" />
      <mass value="0.30296" />
      <inertia ixx="0.00019" ixy="0" ixz="0" iyy="0.0002" iyz="0" izz="0.00032" />
    </inertial>
    <visual>
      <origin xyz="0 0 0" rpy="0 0 0" />
      <geometry>
        <mesh filename="package://aubo_description/meshes/aubo_G10/visual/link6.DAE" />
      </geometry>
      <material name="">
        <color rgba="1 1 1 1" />
      </material>
    </visual>
    <collision>
      <origin xyz="0 0 0" rpy="0 0 0" />
      <geometry>
        <mesh filename="package://aubo_description/meshes/aubo_G10/collision/link6.STL" />
      </geometry>
    </collision>
  </link>

  <joint name="joint6" type="revolute">
    <origin xyz="0 -0.102 0" rpy="1.5707963267948966192313216916398 0 1.7907E-15" />
    <parent link="link5" />
    <child link="link6" />
    <axis xyz="0 0 1" />
    <limit lower="-6.283185307179586476925286766559" upper="6.283185307179586476925286766559" effort="14" start_stop="30" velocity="8.901179" />
    <property inertia="0.25" damping="0" stiffness="0" offset="0" motor_constant="8.81" ratio="80"/>
  </joint>

  <link name="world" />

  <joint name="joint0" type="fixed">
    <parent link="world" />
    <child link = "link0" />
    <origin xyz="0.0 0.0 0.0" rpy="0.0 0.0 0.0" />
  </joint>
</robot>
