<?xml version="1.0"?>
<robot name="aubo_G16">
  <dh_type type="modified"/>
  <safety_para singularity_consistent="0.02 0.01 10 0.2 0.045 10"/>
  <link name="link0">
    <inertial>
      <origin xyz="0.000136 0.001601 0.018986" rpy="0 0 0" />
      <mass value="2.592" />
      <inertia ixx="0.008524" ixy="-0.000001" ixz="-0.000005" iyy="0.007934" iyz="-0.000081" izz="0.015304" />
    </inertial>
    <visual>
      <origin xyz="0 0 0" rpy="0 0 0" />
      <geometry>
        <mesh filename="package://aubo_description/meshes/aubo_G16/visual/link0.DAE" />
      </geometry>
      <material name="">
        <color rgba="1 1 1 1" />
      </material>
    </visual>
    <collision>
      <origin xyz="0 0 0" rpy="0 0 0" />
      <geometry>
        <mesh filename="package://aubo_description/meshes/aubo_G16/collision/link0.STL" />
      </geometry>
    </collision>
  </link>


  <link name="link1">
    <inertial>
      <origin xyz="-0.000004 0.005112 -0.026275" rpy="0 0 0" />
      <mass value="10.180139" />
      <inertia ixx="0.043326" ixy="0.000003" ixz="0.000003" iyy="0.042233" iyz="-0.001767" izz="0.029902" />
    </inertial>
    <visual>
      <origin xyz="0 0 0" rpy="0 0 0" />
      <geometry>
        <mesh
          filename="package://aubo_description/meshes/aubo_G16/visual/link1.DAE" />
      </geometry>
      <material name="">
        <color rgba="0.89804 0.91765 0.92941 1" />
      </material>
    </visual>
    <collision>
      <origin xyz="0 0 0" rpy="0 0 0" />
      <geometry>
        <mesh filename="package://aubo_description/meshes/aubo_G16/collision/link1.STL" />
      </geometry>
    </collision>
  </link>


  <joint name="joint1" type="revolute">
    <origin xyz="0 0 0.163" rpy="0 0 3.1415926535897932384626433832795" />
    <parent link="link0" />
    <child link="link1" />
    <axis xyz="0 0 1" />
    <limit lower="-6.283185307179586476925286766559" upper="6.283185307179586476925286766559" effort="281" start_stop="433" velocity="5.026548" />
    <property inertia="4.9" damping="0" stiffness="0" offset="0" motor_constant="8.75" ratio="101"/>
  </joint>


  <link name="link2">
    <inertial>
      <origin xyz="0.170602 0.0000 -0.013024" rpy="0 0 0" />
      <mass value="17.66406" />
      <inertia ixx="0.063521" ixy="0.00002" ixz="-0.024888" iyy="0.847528" iyz="0.000005" izz="0.828847" />
    </inertial>
    <visual>
      <origin xyz="0 0 0" rpy="0 0 0" />
      <geometry>
        <mesh filename="package://aubo_description/meshes/aubo_G16/visual/link2.DAE" />
      </geometry>
      <material name="">
        <color rgba="0.89804 0.91765 0.92941 1" />
      </material>
    </visual>
    <collision>
      <origin xyz="0 0 0" rpy="0 0 0" />
      <geometry>
        <mesh filename="package://aubo_description/meshes/aubo_G16/collision/link2.STL" />
      </geometry>
    </collision>
  </link>


  <joint name="joint2" type="revolute">
    <origin xyz="0 0.191 0" rpy="-1.5707963267948966192313216916398 -1.5707963267948966192313216916398 0" />
    <parent link="link1" />
    <child link="link2" />
    <axis xyz="0 0 1" />
    <limit lower="-6.283185307179586476925286766559" upper="6.283185307179586476925286766559" effort="281" start_stop="433" velocity="5.026548" />
    <property inertia="4.9" damping="0" stiffness="0" offset="0" motor_constant="8.75" ratio="101"/>
  </joint>


  <link name="link3">
    <inertial>
      <origin xyz="0.269208 -0.000022 0.106467" rpy="0 0 0" />
      <mass value="3.926354" />
      <inertia ixx="0.006007" ixy="0.000009" ixz="0.001991" iyy="0.08378" iyz="0.000005" izz="0.082433" />
    </inertial>
    <visual>
      <origin xyz="0 0 0" rpy="0 0 0" />
      <geometry>
        <mesh filename="package://aubo_description/meshes/aubo_G16/visual/link3.DAE" />
      </geometry>
      <material name="">
        <color rgba="1 1 1 1" />
      </material>
    </visual>
    <collision>
      <origin xyz="0 0 0" rpy="0 0 0" />
      <geometry>
        <mesh filename="package://aubo_description/meshes/aubo_G16/collision/link3.STL" />
      </geometry>
    </collision>
  </link>


  <joint name="foreArm_joint" type="revolute">
    <origin xyz="0.480 0 0" rpy="-3.1415926535897932384626433832795 0 0" />
    <parent link="link2" />
    <child link="link3" />
    <axis xyz="0 0 1" />
    <limit lower="-6.283185307179586476925286766559" upper="6.283185307179586476925286766559" effort="140" start_stop="204" velocity="5.864306" />
    <property inertia="2.0" damping="0" stiffness="0" offset="0" motor_constant="8.72" ratio="101"/>
  </joint>


  <link name="link4">
    <inertial>
      <origin xyz="0.000036 0.01561 -0.001526" rpy="0 0 0" />
      <mass value="2.370741" />
      <inertia ixx="0.003672" ixy="0.000006" ixz="-0.000001" iyy="0.00219" iyz="-0.00008" izz="0.003621" />
    </inertial>
    <visual>
      <origin xyz="0 0 0" rpy="0 0 0" />
      <geometry>
        <mesh filename="package://aubo_description/meshes/aubo_G16/visual/link4.DAE" />
      </geometry>
      <material name="">
        <color rgba="1 1 1 1" />
      </material>
    </visual>
    <collision>
      <origin xyz="0 0 0" rpy="0 0 0" />
      <geometry>
        <mesh filename="package://aubo_description/meshes/aubo_G16/collision/link4.STL" />
      </geometry>
    </collision>
  </link>


  <joint name="joint4" type="revolute">
    <origin xyz="0.370 0 0" rpy="3.1415926535897932384626433832795 0 1.5707963267948966192313216916398" />
    <parent link="link3" />
    <child link="link4" />
    <axis xyz="0 0 1" />
    <limit lower="-6.283185307179586476925286766559" upper="6.283185307179586476925286766559" effort="51" start_stop="70" velocity="7.644542" />
    <property inertia="0" damping="0" stiffness="0" offset="0" motor_constant="8.81" ratio="101"/>
  </joint>


  <link name="link5">
    <inertial>
      <origin xyz="-0.000036 -0.01561 -0.001526" rpy="0 0 0" />
      <mass value="2.370741" />
      <inertia ixx="0.003672" ixy="0.000006" ixz="0.000001" iyy="0.00219" iyz="0.00008" izz="0.003621" />
    </inertial>
    <visual>
      <origin xyz="0 0 0" rpy="0 0 0" />
      <geometry>
        <mesh filename="package://aubo_description/meshes/aubo_G16/visual/link5.DAE" />
      </geometry>
      <material name="">
        <color rgba="1 1 1 1" />
      </material>
    </visual>
    <collision>
      <origin xyz="0 0 0" rpy="0 0 0" />
      <geometry>
        <mesh filename="package://aubo_description/meshes/aubo_G16/collision/link5.STL" />
      </geometry>
    </collision>
  </link>


  <joint name="joint5" type="revolute">
    <origin xyz="0 0.1175 0" rpy="-1.5707963267948966192313216916398 0 0" />
    <parent link="link4" />
    <child link="link5" />
    <axis xyz="0 0 1" />
    <limit lower="-6.283185307179586476925286766559" upper="6.283185307179586476925286766559" effort="51" start_stop="70" velocity="7.644542" />
    <property inertia="0" damping="0" stiffness="0" offset="0" motor_constant="8.81" ratio="101"/>
  </joint>


  <link name="link6">
    <inertial>
      <origin xyz="0.000508 0.000344 -0.017049" rpy="0 0 0" />
      <mass value="0.259654" />
      <inertia ixx="0.000162" ixy="0.0000" ixz="0.0000" iyy="0.000162" iyz="0.000001" izz="0.000273" />
    </inertial>
    <visual>
      <origin xyz="0 0 0" rpy="0 0 0" />
      <geometry>
        <mesh filename="package://aubo_description/meshes/aubo_G16/visual/link6.DAE" />
      </geometry>
      <material name="">
        <color rgba="1 1 1 1" />
      </material>
    </visual>
    <collision>
      <origin xyz="0 0 0" rpy="0 0 0" />
      <geometry>
        <mesh filename="package://aubo_description/meshes/aubo_G16/collision/link6.STL" />
      </geometry>
    </collision>
  </link>


  <joint name="joint6" type="revolute">
    <origin xyz="0 -0.1035 0" rpy="1.5707963267948966192313216916398 0 0" />
    <parent link="link5" />
    <child link="link6" />
    <axis xyz="0 0 1" />
    <limit lower="-6.283185307179586476925286766559" upper="6.283185307179586476925286766559" effort="51" start_stop="70" velocity="7.644542" />
    <property inertia="0" damping="0" stiffness="0" offset="0" motor_constant="8.81" ratio="101"/>
  </joint>

  <link name="world" />

  <joint name="joint0" type="fixed">
    <parent link="world" />
    <child link = "link0" />
    <origin xyz="0.0 0.0 0.0" rpy="0.0 0.0 0.0" />
  </joint>

</robot>
