<?xml version="1.0"?>
<robot  name="aubo_iS3_10">
  <dh_type type="modified"/>
  <safety_para singularity_consistent="0.02 0.01 10 0.2 0.045 10"/>	
  <link name="base_link">
    <inertial>
      <origin xyz="0.000145 -0.000526 0.034207" rpy="0 0 0" />
      <mass value="1.412307" />
      <inertia ixx="0.002893" ixy="-0.000001" ixz="0.000002" iyy="0.002866" iyz="-0.000011" izz="0.003975" />
    </inertial>
    <visual>
      <origin xyz="0 0 0" rpy="0 0 0" />
      <geometry>
        <mesh filename="package://aubo_description/meshes/aubo_iS3_10/visual/link0.DAE" />
      </geometry>
      <material name="">
        <color rgba="1 1 1 1" />
      </material>
    </visual>
    <collision>
      <origin xyz="0 0 0" rpy="0 0 0" />
      <geometry>
        <mesh filename="package://aubo_description/meshes/aubo_iS3_10/collision/link0.STL" />
      </geometry>
    </collision>
  </link>

  <link name="shoulder_Link">
    <inertial>
      <origin xyz="-0.000014 0.001713 -0.019537" rpy="0 0 0" />
      <mass value="2.906210" />
      <inertia ixx="0.004711" ixy="-0.000001" ixz="0.000001" iyy="0.004690" iyz="-0.000119" izz="0.003359" />
    </inertial>
    <visual>
      <origin xyz="0 0 0" rpy="0 0 0" />
      <geometry>
        <mesh filename="package://aubo_description/meshes/aubo_iS3_10/visual/link1.DAE" />
      </geometry>
      <material name="">
        <color rgba="1 1 1 1" />
      </material>
    </visual>
    <collision>
      <origin xyz="0 0 0" rpy="0 0 0" />
      <geometry>
        <mesh filename="package://aubo_description/meshes/aubo_iS3_10/collision/link1.STL" />
      </geometry>
    </collision>
  </link>

  <joint name="shoulder_joint" type="revolute">
    <origin xyz="0 0 0.156" rpy="0 0 3.1415926535897932384626433832795" />
    <parent link="base_link" />
    <child link="shoulder_Link" />
    <axis xyz="0 0 1" />
    <limit lower="-6.283185307179586476925286766559" upper="6.283185307179586476925286766559" effort="61" start_stop="102" velocity="3.1104877758314784539234092903757" />
    <property inertia="0" damping="0" stiffness="0" offset="0" motor_constant="8.58" ratio="101"/>
  </joint>

  <link name="upperArm_Link">
    <inertial>
      <origin xyz="0.116495 0.000006 -0.016602" rpy="0 0 0" />
      <mass value="5.583211" />
      <inertia ixx="0.008619" ixy="0.000007" ixz="-0.001257" iyy="0.096760" iyz="-0.000001" izz="0.094072" />
    </inertial>
    <visual>
      <origin xyz="0 0 0" rpy="0 0 0" />
      <geometry>
        <mesh filename="package://aubo_description/meshes/aubo_iS3_10/visual/link2.DAE" />
      </geometry>
      <material name="">
        <color rgba="1 1 1 1" />
      </material>
    </visual>
    <collision>
      <origin xyz="0 0 0" rpy="0 0 0" />
      <geometry>
        <mesh filename="package://aubo_description/meshes/aubo_iS3_10/collision/link2.STL" />
      </geometry>
    </collision>
  </link>

  <joint name="upperArm_joint" type="revolute">
    <origin xyz="0 0.1205 0" rpy="-1.5707963267948966192313216916398 -1.5707963267948966192313216916398 0" />
    <parent link="shoulder_Link" />
    <child link="upperArm_Link" />
    <axis xyz="0 0 1" />
    <limit lower="-6.283185307179586476925286766559" upper="6.283185307179586476925286766559" effort="61" start_stop="102" velocity="3.1104877758314784539234092903757" />
    <property inertia="0" damping="0" stiffness="0" offset="0" motor_constant="8.58" ratio="101"/>
  </joint>

  <link name="foreArm_Link">
    <inertial>
      <origin xyz="0.198096 0.001004 0.095317" rpy="0 0 0" />
      <mass  value="2.199571" />
      <inertia ixx="0.002384" ixy="-0.000096" ixz="0.000641" iyy="0.021203" iyz="0.000004" izz="0.020596" />
    </inertial>
    <visual>
      <origin xyz="0 0 0" rpy="0 0 0" />
      <geometry>
        <mesh filename="package://aubo_description/meshes/aubo_iS3_10/visual/link3.DAE" />
      </geometry>
      <material name="">
        <color rgba="1 1 1 1" />
      </material>
    </visual>
    <collision>
      <origin xyz="0 0 0" rpy="0 0 0" />
      <geometry>
        <mesh filename="package://aubo_description/meshes/aubo_iS3_10/collision/link3.STL" />
      </geometry>
    </collision>
  </link>

  <joint name="foreArm_joint" type="revolute">
    <origin xyz="0.266 0 0" rpy="-3.1415926535897932384626433832795 0 0" />
    <parent link="upperArm_Link" />
    <child link="foreArm_Link" />
    <axis xyz="0 0 1" />
    <limit lower="-6.283185307179586476925286766559" upper="6.283185307179586476925286766559" effort="49" start_stop="66" velocity="3.1104877758314784539234092903757" />
    <property inertia="0" damping="0" stiffness="0" offset="0" motor_constant="8.81" ratio="101"/>
  </joint>

  <link name="wrist1_Link">
    <inertial>
      <origin xyz="0.000022 0.014886 -0.001687" rpy="0 0 0" />
      <mass value="1.505192" />
      <inertia ixx="0.001628" ixy="0.000001" ixz="0.000001" iyy="0.001015" iyz="-0.000042" izz="0.001603" />
    </inertial>
    <visual>
      <origin xyz="0 0 0" rpy="0 0 0" />
      <geometry>
        <mesh filename="package://aubo_description/meshes/aubo_iS3_10/visual/link4.DAE" />
      </geometry>
      <material name="">
        <color rgba="1 1 1 1" />
      </material>
    </visual>
    <collision>
      <origin xyz="0 0 0" rpy="0 0 0" />
      <geometry>
        <mesh filename="package://aubo_description/meshes/aubo_iS3_10/collision/link4.STL" />
      </geometry>
    </collision>
  </link>

  <joint name="wrist1_joint" type="revolute">
    <origin xyz="0.2565 0 0" rpy="3.1415926535897932384626433832795 0 1.5707963267948966192313216916398" />
    <parent link="foreArm_Link" />
    <child link="wrist1_Link" />
    <axis xyz="0 0 1" />
    <limit lower="-6.283185307179586476925286766559" upper="6.283185307179586476925286766559" effort="13.5" start_stop="34" velocity="3.1104877758314784539234092903757" />
    <property inertia="0" damping="0" stiffness="0" offset="0" motor_constant="7.092" ratio="101"/>
  </joint>

  <link name="wrist2_Link">
    <inertial>
      <origin xyz="-0.000022 -0.014886 -0.001687" rpy="0 0 0" />
      <mass value="1.505192" />
      <inertia ixx="0.001628" ixy="0.000001" ixz="0.000001" iyy="0.001015" iyz="-0.000042" izz="0.001603" />
    </inertial>
    <visual>
      <origin xyz="0 0 0" rpy="0 0 0" />
      <geometry>
        <mesh filename="package://aubo_description/meshes/aubo_iS3_10/visual/link5.DAE" />
      </geometry>
      <material name="">
        <color rgba="1 1 1 1" />
      </material>
    </visual>
    <collision>
      <origin xyz="0 0 0" rpy="0 0 0" />
      <geometry>
        <mesh filename="package://aubo_description/meshes/aubo_iS3_10/collision/link5.STL" />
      </geometry>
    </collision>
  </link>

  <joint name="wrist2_joint" type="revolute">
    <origin xyz="0 0.1025 0" rpy="-1.5707963267948966192313216916398 0 0" />
    <parent link="wrist1_Link" />
    <child link="wrist2_Link" />
    <axis xyz="0 0 1" />
    <limit lower="-6.283185307179586476925286766559" upper="6.283185307179586476925286766559" effort="13.5" start_stop="34" velocity="3.1104877758314784539234092903757" />
    <property inertia="0" damping="0" stiffness="0" offset="0" motor_constant="7.092" ratio="101"/>
  </joint>

  <link name="wrist3_Link">
    <inertial>
      <origin xyz="0.000826 -0.000398 -0.017152" rpy="0 0 0" />
      <mass value="0.238363" />
      <inertia ixx="0.000126" ixy="0.000002" ixz="0.000001" iyy="0.000130" iyz="-0.000001" izz="0.000207" />
    </inertial>
    <visual>
      <origin xyz="0 0 0" rpy="0 0 0" />
      <geometry>
        <mesh filename="package://aubo_description/meshes/aubo_iS3_10/visual/link6.DAE" />
      </geometry>
      <material name="">
        <color rgba="1 1 1 1" />
      </material>
    </visual>
    <collision>
      <origin xyz="0 0 0" rpy="0 0 0" />
      <geometry>
        <mesh filename="package://aubo_description/meshes/aubo_iS3_10/collision/link6.STL" />
      </geometry>
    </collision>
  </link>

  <joint name="wrist3_joint" type="revolute">
    <origin xyz="0 -0.094 0" rpy="1.5707963267948966192313216916398 0 1.7907E-15" />
    <parent link="wrist2_Link" />
    <child link="wrist3_Link" />
    <axis xyz="0 0 1" />
    <limit lower="-6.283185307179586476925286766559" upper="6.283185307179586476925286766559" effort="13.5" start_stop="34" velocity="3.1104877758314784539234092903757" />
    <property inertia="0" damping="0" stiffness="0" offset="0" motor_constant="7.092" ratio="101"/>
  </joint>

  <link name="world" />

  <joint name="world_joint" type="fixed">
    <parent link="world" />
    <child link = "base_link" />
    <origin xyz="0.0 0.0 0.0" rpy="0.0 0.0 0.0" />
  </joint>
</robot>
